2022-01-19:19:33:34,240 DEBUG    [connectionpool.py:228] Starting new HTTP connection (1): localhost:5000
2022-01-19:19:33:38,771 INFO     [send_to_server.py:67] {'message': 'name: 79prabal created succesfully! but not send to other server'}
2022-01-19:19:33:38,874 INFO     [send_to_server.py:81] Fetch result:  [('prabal', '79prabal', 0)]
2022-01-19:19:33:38,874 INFO     [send_to_server.py:85] Sending remaining data
2022-01-19:19:33:38,877 DEBUG    [connectionpool.py:228] Starting new HTTP connection (1): localhost:5000
2022-01-19:19:33:42,949 ERROR    [send_to_server.py:111] Error in sending data to other server
Traceback (most recent call last):
  File "C:\Users\hp\.virtualenvs\data_prac-rC3M8CAo\lib\site-packages\urllib3\connection.py", line 174, in _new_conn
    conn = connection.create_connection(
  File "C:\Users\hp\.virtualenvs\data_prac-rC3M8CAo\lib\site-packages\urllib3\util\connection.py", line 95, in create_connection
    raise err
  File "C:\Users\hp\.virtualenvs\data_prac-rC3M8CAo\lib\site-packages\urllib3\util\connection.py", line 85, in create_connection
    sock.connect(sa)
ConnectionRefusedError: [WinError 10061] No connection could be made because the target machine actively refused it

During handling of the above exception, another exception occurred:

Traceback (most recent call last):
  File "C:\Users\hp\.virtualenvs\data_prac-rC3M8CAo\lib\site-packages\urllib3\connectionpool.py", line 703, in urlopen
    httplib_response = self._make_request(
  File "C:\Users\hp\.virtualenvs\data_prac-rC3M8CAo\lib\site-packages\urllib3\connectionpool.py", line 398, in _make_request
    conn.request(method, url, **httplib_request_kw)
  File "C:\Users\hp\.virtualenvs\data_prac-rC3M8CAo\lib\site-packages\urllib3\connection.py", line 239, in request
    super(HTTPConnection, self).request(method, url, body=body, headers=headers)
  File "c:\users\hp\appdata\local\programs\python\python39\lib\http\client.py", line 1253, in request
    self._send_request(method, url, body, headers, encode_chunked)
  File "c:\users\hp\appdata\local\programs\python\python39\lib\http\client.py", line 1299, in _send_request
    self.endheaders(body, encode_chunked=encode_chunked)
  File "c:\users\hp\appdata\local\programs\python\python39\lib\http\client.py", line 1248, in endheaders
    self._send_output(message_body, encode_chunked=encode_chunked)
  File "c:\users\hp\appdata\local\programs\python\python39\lib\http\client.py", line 1008, in _send_output
    self.send(msg)
  File "c:\users\hp\appdata\local\programs\python\python39\lib\http\client.py", line 948, in send
    self.connect()
  File "C:\Users\hp\.virtualenvs\data_prac-rC3M8CAo\lib\site-packages\urllib3\connection.py", line 205, in connect
    conn = self._new_conn()
  File "C:\Users\hp\.virtualenvs\data_prac-rC3M8CAo\lib\site-packages\urllib3\connection.py", line 186, in _new_conn
    raise NewConnectionError(
urllib3.exceptions.NewConnectionError: <urllib3.connection.HTTPConnection object at 0x000002BB80A2B580>: Failed to establish a new connection: [WinError 10061] No connection could be made because the target machine actively refused it

During handling of the above exception, another exception occurred:

Traceback (most recent call last):
  File "C:\Users\hp\.virtualenvs\data_prac-rC3M8CAo\lib\site-packages\requests\adapters.py", line 440, in send
    resp = conn.urlopen(
  File "C:\Users\hp\.virtualenvs\data_prac-rC3M8CAo\lib\site-packages\urllib3\connectionpool.py", line 785, in urlopen
    retries = retries.increment(
  File "C:\Users\hp\.virtualenvs\data_prac-rC3M8CAo\lib\site-packages\urllib3\util\retry.py", line 592, in increment
    raise MaxRetryError(_pool, url, error or ResponseError(cause))
urllib3.exceptions.MaxRetryError: HTTPConnectionPool(host='localhost', port=5000): Max retries exceeded with url: / (Caused by NewConnectionError('<urllib3.connection.HTTPConnection object at 0x000002BB80A2B580>: Failed to establish a new connection: [WinError 10061] No connection could be made because the target machine actively refused it'))

During handling of the above exception, another exception occurred:

Traceback (most recent call last):
  File "C:\Users\hp\flask_apps\data_prac\send_to_server.py", line 99, in send_remain_data
    send_data = requests.post("http://localhost:5000/", json=data)
  File "C:\Users\hp\.virtualenvs\data_prac-rC3M8CAo\lib\site-packages\requests\api.py", line 117, in post
    return request('post', url, data=data, json=json, **kwargs)
  File "C:\Users\hp\.virtualenvs\data_prac-rC3M8CAo\lib\site-packages\requests\api.py", line 61, in request
    return session.request(method=method, url=url, **kwargs)
  File "C:\Users\hp\.virtualenvs\data_prac-rC3M8CAo\lib\site-packages\requests\sessions.py", line 529, in request
    resp = self.send(prep, **send_kwargs)
  File "C:\Users\hp\.virtualenvs\data_prac-rC3M8CAo\lib\site-packages\requests\sessions.py", line 645, in send
    r = adapter.send(request, **kwargs)
  File "C:\Users\hp\.virtualenvs\data_prac-rC3M8CAo\lib\site-packages\requests\adapters.py", line 519, in send
    raise ConnectionError(e, request=request)
requests.exceptions.ConnectionError: HTTPConnectionPool(host='localhost', port=5000): Max retries exceeded with url: / (Caused by NewConnectionError('<urllib3.connection.HTTPConnection object at 0x000002BB80A2B580>: Failed to establish a new connection: [WinError 10061] No connection could be made because the target machine actively refused it'))
2022-01-19:19:33:43,66 INFO     [send_to_server.py:116] Host is down
2022-01-19:19:34:35,631 DEBUG    [connectionpool.py:228] Starting new HTTP connection (1): localhost:5000
2022-01-19:19:34:37,962 DEBUG    [connectionpool.py:456] http://localhost:5000 "POST / HTTP/1.1" 200 53
2022-01-19:19:34:40,666 INFO     [send_to_server.py:59] name: 50prabal created succesfully!  send to other server
2022-01-19:19:34:41,414 INFO     [send_to_server.py:81] Fetch result:  [('prabal', '79prabal', 0)]
2022-01-19:19:34:41,414 INFO     [send_to_server.py:85] Sending remaining data
2022-01-19:19:34:41,416 DEBUG    [connectionpool.py:228] Starting new HTTP connection (1): localhost:5000
2022-01-19:19:34:43,780 DEBUG    [connectionpool.py:456] http://localhost:5000 "POST / HTTP/1.1" 200 53
2022-01-19:19:34:43,781 INFO     [send_to_server.py:103] Updating data
2022-01-19:19:34:44,140 INFO     [send_to_server.py:108] 79prabal Successfully send to other server
2022-01-19:22:49:30,679 DEBUG    [connectionpool.py:228] Starting new HTTP connection (1): localhost:5000
2022-01-19:22:49:39,182 INFO     [send_to_server.py:67] {'message': 'name: 61prabal created succesfully! but not send to other server'}
2022-01-19:22:49:52,913 DEBUG    [connectionpool.py:228] Starting new HTTP connection (1): localhost:5000
2022-01-19:22:49:57,591 INFO     [send_to_server.py:67] {'message': 'name: 34prabal created succesfully! but not send to other server'}
